reported_result/report-5/ART_AutoISP2/output/output2.txt

Limit	1	3	2	2	4	SELL	0	---	0
NewOrderRs	Accepted
	Trades	0
	Orders	1
	Order	Limit	1	3	2	2	4	SELL	0	---	0
	Credits	7
	Credit	1	9
	Credit	2	11
	Credit	3	14
	Credit	4	15
	Credit	5	11
	Credit	6	10
	Credit	7	11
	Ownerships	7
	Ownership	1	50
	Ownership	2	29
	Ownership	3	57
	Ownership	4	51
	Ownership	5	46
	Ownership	6	55
	Ownership	7	58
	ReferencePrice	5
	StaticPriceBandLowerLimit	0.6
	StaticPriceBandUpperLimit	0.8
	TotalShares	100
	OwnershipUpperLimit	0.2
	TickSize	1
	LotSize	1
Iceberg	2	5	1	7	3	BUY 	1	---	0
NewOrderRs	Rejected
	Trades	0
	Orders	1
	Order	Limit	1	3	2	2	4	SELL	0	---	0
	Credits	7
	Credit	1	9
	Credit	2	11
	Credit	3	14
	Credit	4	15
	Credit	5	11
	Credit	6	10
	Credit	7	11
	Ownerships	7
	Ownership	1	50
	Ownership	2	29
	Ownership	3	57
	Ownership	4	51
	Ownership	5	46
	Ownership	6	55
	Ownership	7	58
	ReferencePrice	5
	StaticPriceBandLowerLimit	0.6
	StaticPriceBandUpperLimit	0.8
	TotalShares	100
	OwnershipUpperLimit	0.2
	TickSize	1
	LotSize	1
Iceberg	3	7	3	2	7	SELL	0	---	0
NewOrderRs	Accepted
	Trades	0
	Orders	2
	Order	Limit	1	3	2	2	4	SELL	0	---	0
	Order	Iceberg	3	7	3	2	7	SELL	0	---	2
	Credits	7
	Credit	1	9
	Credit	2	11
	Credit	3	14
	Credit	4	15
	Credit	5	11
	Credit	6	10
	Credit	7	11
	Ownerships	7
	Ownership	1	50
	Ownership	2	29
	Ownership	3	57
	Ownership	4	51
	Ownership	5	46
	Ownership	6	55
	Ownership	7	58
	ReferencePrice	5
	StaticPriceBandLowerLimit	0.6
	StaticPriceBandUpperLimit	0.8
	TotalShares	100
	OwnershipUpperLimit	0.2
	TickSize	1
	LotSize	1
Limit	4	5	7	4	1	BUY 	0	---	0
NewOrderRs	Rejected
	Trades	0
	Orders	2
	Order	Limit	1	3	2	2	4	SELL	0	---	0
	Order	Iceberg	3	7	3	2	7	SELL	0	---	2
	Credits	7
	Credit	1	9
	Credit	2	11
	Credit	3	14
	Credit	4	15
	Credit	5	11
	Credit	6	10
	Credit	7	11
	Ownerships	7
	Ownership	1	50
	Ownership	2	29
	Ownership	3	57
	Ownership	4	51
	Ownership	5	46
	Ownership	6	55
	Ownership	7	58
	ReferencePrice	5
	StaticPriceBandLowerLimit	0.6
	StaticPriceBandUpperLimit	0.8
	TotalShares	100
	OwnershipUpperLimit	0.2
	TickSize	1
	LotSize	1
CancelOrderRs	Rejected
	Orders	2
	Order	Limit	1	3	2	2	4	SELL	0	---	0
	Order	Iceberg	3	7	3	2	7	SELL	0	---	2
	Credits	7
	Credit	1	9
	Credit	2	11
	Credit	3	14
	Credit	4	15
	Credit	5	11
	Credit	6	10
	Credit	7	11
	Ownerships	7
	Ownership	1	50
	Ownership	2	29
	Ownership	3	57
	Ownership	4	51
	Ownership	5	46
	Ownership	6	55
	Ownership	7	58
	ReferencePrice	5
	StaticPriceBandLowerLimit	0.6
	StaticPriceBandUpperLimit	0.8
	TotalShares	100
	OwnershipUpperLimit	0.2
	TickSize	1
	LotSize	1
Iceberg	6	7	2	4	4	BUY 	3	---	0
NewOrderRs	Rejected
	Trades	0
	Orders	2
	Order	Limit	1	3	2	2	4	SELL	0	---	0
	Order	Iceberg	3	7	3	2	7	SELL	0	---	2
	Credits	7
	Credit	1	9
	Credit	2	11
	Credit	3	14
	Credit	4	15
	Credit	5	11
	Credit	6	10
	Credit	7	11
	Ownerships	7
	Ownership	1	50
	Ownership	2	29
	Ownership	3	57
	Ownership	4	51
	Ownership	5	46
	Ownership	6	55
	Ownership	7	58
	ReferencePrice	5
	StaticPriceBandLowerLimit	0.6
	StaticPriceBandUpperLimit	0.8
	TotalShares	100
	OwnershipUpperLimit	0.2
	TickSize	1
	LotSize	1
Iceberg	7	5	5	2	6	BUY 	2	---	0
NewOrderRs	Rejected
	Trades	0
	Orders	2
	Order	Limit	1	3	2	2	4	SELL	0	---	0
	Order	Iceberg	3	7	3	2	7	SELL	0	---	2
	Credits	7
	Credit	1	9
	Credit	2	11
	Credit	3	14
	Credit	4	15
	Credit	5	11
	Credit	6	10
	Credit	7	11
	Ownerships	7
	Ownership	1	50
	Ownership	2	29
	Ownership	3	57
	Ownership	4	51
	Ownership	5	46
	Ownership	6	55
	Ownership	7	58
	ReferencePrice	5
	StaticPriceBandLowerLimit	0.6
	StaticPriceBandUpperLimit	0.8
	TotalShares	100
	OwnershipUpperLimit	0.2
	TickSize	1
	LotSize	1
Limit	8	6	3	2	5	BUY 	0	---	0
NewOrderRs	Rejected
	Trades	0
	Orders	2
	Order	Limit	1	3	2	2	4	SELL	0	---	0
	Order	Iceberg	3	7	3	2	7	SELL	0	---	2
	Credits	7
	Credit	1	9
	Credit	2	11
	Credit	3	14
	Credit	4	15
	Credit	5	11
	Credit	6	10
	Credit	7	11
	Ownerships	7
	Ownership	1	50
	Ownership	2	29
	Ownership	3	57
	Ownership	4	51
	Ownership	5	46
	Ownership	6	55
	Ownership	7	58
	ReferencePrice	5
	StaticPriceBandLowerLimit	0.6
	StaticPriceBandUpperLimit	0.8
	TotalShares	100
	OwnershipUpperLimit	0.2
	TickSize	1
	LotSize	1
Limit	9	5	1	8	4	SELL	0	---	0
NewOrderRs	Accepted
	Trades	0
	Orders	3
	Order	Limit	1	3	2	2	4	SELL	0	---	0
	Order	Iceberg	3	7	3	2	7	SELL	0	---	2
	Order	Limit	9	5	1	8	4	SELL	0	---	0
	Credits	7
	Credit	1	9
	Credit	2	11
	Credit	3	14
	Credit	4	15
	Credit	5	11
	Credit	6	10
	Credit	7	11
	Ownerships	7
	Ownership	1	50
	Ownership	2	29
	Ownership	3	57
	Ownership	4	51
	Ownership	5	46
	Ownership	6	55
	Ownership	7	58
	ReferencePrice	5
	StaticPriceBandLowerLimit	0.6
	StaticPriceBandUpperLimit	0.8
	TotalShares	100
	OwnershipUpperLimit	0.2
	TickSize	1
	LotSize	1
Iceberg	10	5	1	5	8	SELL	0	---	0
ReplaceOrderRs	Accepted
	Trades	0
	Orders	3
	Order	Limit	1	3	2	2	4	SELL	0	---	0
	Order	Iceberg	3	7	3	2	7	SELL	0	---	2
	Order	Iceberg	10	5	1	5	8	SELL	0	---	3
	Credits	7
	Credit	1	9
	Credit	2	11
	Credit	3	14
	Credit	4	15
	Credit	5	11
	Credit	6	10
	Credit	7	11
	Ownerships	7
	Ownership	1	50
	Ownership	2	29
	Ownership	3	57
	Ownership	4	51
	Ownership	5	46
	Ownership	6	55
	Ownership	7	58
	ReferencePrice	5
	StaticPriceBandLowerLimit	0.6
	StaticPriceBandUpperLimit	0.8
	TotalShares	100
	OwnershipUpperLimit	0.2
	TickSize	1
	LotSize	1
