reported_result/report-5/ART_AutoISP/output/output3.txt

Limit	1	2	2	2	6	SELL	0	---	0
NewOrderRs	Accepted
	Trades	0
	Orders	1
	Order	Limit	1	2	2	2	6	SELL	0	---	0
	Credits	7
	Credit	1	11
	Credit	2	1
	Credit	3	14
	Credit	4	10
	Credit	5	3
	Credit	6	15
	Credit	7	1
	Ownerships	7
	Ownership	1	94
	Ownership	2	23
	Ownership	3	49
	Ownership	4	18
	Ownership	5	7
	Ownership	6	63
	Ownership	7	84
	ReferencePrice	5
	StaticPriceBandLowerLimit	0.6
	StaticPriceBandUpperLimit	0.8
	TotalShares	100
	OwnershipUpperLimit	0.2
	TickSize	1
	LotSize	1
Limit	2	2	4	4	6	BUY 	0	FAK	0
NewOrderRs	Rejected
	Trades	0
	Orders	1
	Order	Limit	1	2	2	2	6	SELL	0	---	0
	Credits	7
	Credit	1	11
	Credit	2	1
	Credit	3	14
	Credit	4	10
	Credit	5	3
	Credit	6	15
	Credit	7	1
	Ownerships	7
	Ownership	1	94
	Ownership	2	23
	Ownership	3	49
	Ownership	4	18
	Ownership	5	7
	Ownership	6	63
	Ownership	7	84
	ReferencePrice	5
	StaticPriceBandLowerLimit	0.6
	StaticPriceBandUpperLimit	0.8
	TotalShares	100
	OwnershipUpperLimit	0.2
	TickSize	1
	LotSize	1
Limit	3	6	4	7	4	SELL	0	---	0
NewOrderRs	Accepted
	Trades	0
	Orders	2
	Order	Limit	1	2	2	2	6	SELL	0	---	0
	Order	Limit	3	6	4	7	4	SELL	0	---	0
	Credits	7
	Credit	1	11
	Credit	2	1
	Credit	3	14
	Credit	4	10
	Credit	5	3
	Credit	6	15
	Credit	7	1
	Ownerships	7
	Ownership	1	94
	Ownership	2	23
	Ownership	3	49
	Ownership	4	18
	Ownership	5	7
	Ownership	6	63
	Ownership	7	84
	ReferencePrice	5
	StaticPriceBandLowerLimit	0.6
	StaticPriceBandUpperLimit	0.8
	TotalShares	100
	OwnershipUpperLimit	0.2
	TickSize	1
	LotSize	1
Limit	4	3	4	5	3	SELL	0	FAK	0
NewOrderRs	Eliminated
	Trades	0
	Orders	2
	Order	Limit	1	2	2	2	6	SELL	0	---	0
	Order	Limit	3	6	4	7	4	SELL	0	---	0
	Credits	7
	Credit	1	11
	Credit	2	1
	Credit	3	14
	Credit	4	10
	Credit	5	3
	Credit	6	15
	Credit	7	1
	Ownerships	7
	Ownership	1	94
	Ownership	2	23
	Ownership	3	49
	Ownership	4	18
	Ownership	5	7
	Ownership	6	63
	Ownership	7	84
	ReferencePrice	5
	StaticPriceBandLowerLimit	0.6
	StaticPriceBandUpperLimit	0.8
	TotalShares	100
	OwnershipUpperLimit	0.2
	TickSize	1
	LotSize	1
CancelOrderRs	Rejected
	Orders	2
	Order	Limit	1	2	2	2	6	SELL	0	---	0
	Order	Limit	3	6	4	7	4	SELL	0	---	0
	Credits	7
	Credit	1	11
	Credit	2	1
	Credit	3	14
	Credit	4	10
	Credit	5	3
	Credit	6	15
	Credit	7	1
	Ownerships	7
	Ownership	1	94
	Ownership	2	23
	Ownership	3	49
	Ownership	4	18
	Ownership	5	7
	Ownership	6	63
	Ownership	7	84
	ReferencePrice	5
	StaticPriceBandLowerLimit	0.6
	StaticPriceBandUpperLimit	0.8
	TotalShares	100
	OwnershipUpperLimit	0.2
	TickSize	1
	LotSize	1
Limit	6	3	1	3	1	SELL	0	---	0
NewOrderRs	Accepted
	Trades	0
	Orders	3
	Order	Limit	1	2	2	2	6	SELL	0	---	0
	Order	Limit	6	3	1	3	1	SELL	0	---	0
	Order	Limit	3	6	4	7	4	SELL	0	---	0
	Credits	7
	Credit	1	11
	Credit	2	1
	Credit	3	14
	Credit	4	10
	Credit	5	3
	Credit	6	15
	Credit	7	1
	Ownerships	7
	Ownership	1	94
	Ownership	2	23
	Ownership	3	49
	Ownership	4	18
	Ownership	5	7
	Ownership	6	63
	Ownership	7	84
	ReferencePrice	5
	StaticPriceBandLowerLimit	0.6
	StaticPriceBandUpperLimit	0.8
	TotalShares	100
	OwnershipUpperLimit	0.2
	TickSize	1
	LotSize	1
Limit	7	5	2	1	2	SELL	0	---	0
NewOrderRs	Rejected
	Trades	0
	Orders	3
	Order	Limit	1	2	2	2	6	SELL	0	---	0
	Order	Limit	6	3	1	3	1	SELL	0	---	0
	Order	Limit	3	6	4	7	4	SELL	0	---	0
	Credits	7
	Credit	1	11
	Credit	2	1
	Credit	3	14
	Credit	4	10
	Credit	5	3
	Credit	6	15
	Credit	7	1
	Ownerships	7
	Ownership	1	94
	Ownership	2	23
	Ownership	3	49
	Ownership	4	18
	Ownership	5	7
	Ownership	6	63
	Ownership	7	84
	ReferencePrice	5
	StaticPriceBandLowerLimit	0.6
	StaticPriceBandUpperLimit	0.8
	TotalShares	100
	OwnershipUpperLimit	0.2
	TickSize	1
	LotSize	1
Limit	8	5	4	3	8	SELL	0	FAK	0
NewOrderRs	Eliminated
	Trades	0
	Orders	3
	Order	Limit	1	2	2	2	6	SELL	0	---	0
	Order	Limit	6	3	1	3	1	SELL	0	---	0
	Order	Limit	3	6	4	7	4	SELL	0	---	0
	Credits	7
	Credit	1	11
	Credit	2	1
	Credit	3	14
	Credit	4	10
	Credit	5	3
	Credit	6	15
	Credit	7	1
	Ownerships	7
	Ownership	1	94
	Ownership	2	23
	Ownership	3	49
	Ownership	4	18
	Ownership	5	7
	Ownership	6	63
	Ownership	7	84
	ReferencePrice	5
	StaticPriceBandLowerLimit	0.6
	StaticPriceBandUpperLimit	0.8
	TotalShares	100
	OwnershipUpperLimit	0.2
	TickSize	1
	LotSize	1
Limit	9	7	3	3	1	SELL	0	---	0
NewOrderRs	Accepted
	Trades	0
	Orders	4
	Order	Limit	1	2	2	2	6	SELL	0	---	0
	Order	Limit	6	3	1	3	1	SELL	0	---	0
	Order	Limit	9	7	3	3	1	SELL	0	---	0
	Order	Limit	3	6	4	7	4	SELL	0	---	0
	Credits	7
	Credit	1	11
	Credit	2	1
	Credit	3	14
	Credit	4	10
	Credit	5	3
	Credit	6	15
	Credit	7	1
	Ownerships	7
	Ownership	1	94
	Ownership	2	23
	Ownership	3	49
	Ownership	4	18
	Ownership	5	7
	Ownership	6	63
	Ownership	7	84
	ReferencePrice	5
	StaticPriceBandLowerLimit	0.6
	StaticPriceBandUpperLimit	0.8
	TotalShares	100
	OwnershipUpperLimit	0.2
	TickSize	1
	LotSize	1
Limit	10	7	3	9	1	SELL	1	---	0
ReplaceOrderRs	Rejected
	Trades	0
	Orders	4
	Order	Limit	1	2	2	2	6	SELL	0	---	0
	Order	Limit	6	3	1	3	1	SELL	0	---	0
	Order	Limit	9	7	3	3	1	SELL	0	---	0
	Order	Limit	3	6	4	7	4	SELL	0	---	0
	Credits	7
	Credit	1	11
	Credit	2	1
	Credit	3	14
	Credit	4	10
	Credit	5	3
	Credit	6	15
	Credit	7	1
	Ownerships	7
	Ownership	1	94
	Ownership	2	23
	Ownership	3	49
	Ownership	4	18
	Ownership	5	7
	Ownership	6	63
	Ownership	7	84
	ReferencePrice	5
	StaticPriceBandLowerLimit	0.6
	StaticPriceBandUpperLimit	0.8
	TotalShares	100
	OwnershipUpperLimit	0.2
	TickSize	1
	LotSize	1
Limit	11	7	6	9	6	SELL	0	---	0
NewOrderRs	Accepted
	Trades	0
	Orders	5
	Order	Limit	1	2	2	2	6	SELL	0	---	0
	Order	Limit	6	3	1	3	1	SELL	0	---	0
	Order	Limit	9	7	3	3	1	SELL	0	---	0
	Order	Limit	3	6	4	7	4	SELL	0	---	0
	Order	Limit	11	7	6	9	6	SELL	0	---	0
	Credits	7
	Credit	1	11
	Credit	2	1
	Credit	3	14
	Credit	4	10
	Credit	5	3
	Credit	6	15
	Credit	7	1
	Ownerships	7
	Ownership	1	94
	Ownership	2	23
	Ownership	3	49
	Ownership	4	18
	Ownership	5	7
	Ownership	6	63
	Ownership	7	84
	ReferencePrice	5
	StaticPriceBandLowerLimit	0.6
	StaticPriceBandUpperLimit	0.8
	TotalShares	100
	OwnershipUpperLimit	0.2
	TickSize	1
	LotSize	1
Limit	12	7	7	7	6	BUY 	0	---	0
NewOrderRs	Rejected
	Trades	0
	Orders	5
	Order	Limit	1	2	2	2	6	SELL	0	---	0
	Order	Limit	6	3	1	3	1	SELL	0	---	0
	Order	Limit	9	7	3	3	1	SELL	0	---	0
	Order	Limit	3	6	4	7	4	SELL	0	---	0
	Order	Limit	11	7	6	9	6	SELL	0	---	0
	Credits	7
	Credit	1	11
	Credit	2	1
	Credit	3	14
	Credit	4	10
	Credit	5	3
	Credit	6	15
	Credit	7	1
	Ownerships	7
	Ownership	1	94
	Ownership	2	23
	Ownership	3	49
	Ownership	4	18
	Ownership	5	7
	Ownership	6	63
	Ownership	7	84
	ReferencePrice	5
	StaticPriceBandLowerLimit	0.6
	StaticPriceBandUpperLimit	0.8
	TotalShares	100
	OwnershipUpperLimit	0.2
	TickSize	1
	LotSize	1
Iceberg	13	2	3	7	6	SELL	0	---	0
NewOrderRs	Accepted
	Trades	0
	Orders	6
	Order	Limit	1	2	2	2	6	SELL	0	---	0
	Order	Limit	6	3	1	3	1	SELL	0	---	0
	Order	Limit	9	7	3	3	1	SELL	0	---	0
	Order	Limit	3	6	4	7	4	SELL	0	---	0
	Order	Iceberg	13	2	3	7	6	SELL	0	---	3
	Order	Limit	11	7	6	9	6	SELL	0	---	0
	Credits	7
	Credit	1	11
	Credit	2	1
	Credit	3	14
	Credit	4	10
	Credit	5	3
	Credit	6	15
	Credit	7	1
	Ownerships	7
	Ownership	1	94
	Ownership	2	23
	Ownership	3	49
	Ownership	4	18
	Ownership	5	7
	Ownership	6	63
	Ownership	7	84
	ReferencePrice	5
	StaticPriceBandLowerLimit	0.6
	StaticPriceBandUpperLimit	0.8
	TotalShares	100
	OwnershipUpperLimit	0.2
	TickSize	1
	LotSize	1
Iceberg	14	2	3	1	2	SELL	0	---	0
NewOrderRs	Rejected
	Trades	0
	Orders	6
	Order	Limit	1	2	2	2	6	SELL	0	---	0
	Order	Limit	6	3	1	3	1	SELL	0	---	0
	Order	Limit	9	7	3	3	1	SELL	0	---	0
	Order	Limit	3	6	4	7	4	SELL	0	---	0
	Order	Iceberg	13	2	3	7	6	SELL	0	---	3
	Order	Limit	11	7	6	9	6	SELL	0	---	0
	Credits	7
	Credit	1	11
	Credit	2	1
	Credit	3	14
	Credit	4	10
	Credit	5	3
	Credit	6	15
	Credit	7	1
	Ownerships	7
	Ownership	1	94
	Ownership	2	23
	Ownership	3	49
	Ownership	4	18
	Ownership	5	7
	Ownership	6	63
	Ownership	7	84
	ReferencePrice	5
	StaticPriceBandLowerLimit	0.6
	StaticPriceBandUpperLimit	0.8
	TotalShares	100
	OwnershipUpperLimit	0.2
	TickSize	1
	LotSize	1
CancelOrderRs	Rejected
	Orders	6
	Order	Limit	1	2	2	2	6	SELL	0	---	0
	Order	Limit	6	3	1	3	1	SELL	0	---	0
	Order	Limit	9	7	3	3	1	SELL	0	---	0
	Order	Limit	3	6	4	7	4	SELL	0	---	0
	Order	Iceberg	13	2	3	7	6	SELL	0	---	3
