reported_result/report-5/ART_AutoISP/output/output4.txt

Iceberg	1	5	1	4	7	SELL	0	---	0
NewOrderRs	Accepted
	Trades	0
	Orders	1
	Order	Iceberg	1	5	1	4	7	SELL	0	---	3
	Credits	7
	Credit	1	4
	Credit	2	7
	Credit	3	16
	Credit	4	13
	Credit	5	11
	Credit	6	17
	Credit	7	8
	Ownerships	7
	Ownership	1	21
	Ownership	2	21
	Ownership	3	71
	Ownership	4	57
	Ownership	5	61
	Ownership	6	40
	Ownership	7	48
	ReferencePrice	5
	StaticPriceBandLowerLimit	0.6
	StaticPriceBandUpperLimit	0.8
	TotalShares	100
	OwnershipUpperLimit	0.2
	TickSize	1
	LotSize	1
Iceberg	2	5	2	8	1	BUY 	1	---	0
NewOrderRs	Rejected
	Trades	0
	Orders	1
	Order	Iceberg	1	5	1	4	7	SELL	0	---	3
	Credits	7
	Credit	1	4
	Credit	2	7
	Credit	3	16
	Credit	4	13
	Credit	5	11
	Credit	6	17
	Credit	7	8
	Ownerships	7
	Ownership	1	21
	Ownership	2	21
	Ownership	3	71
	Ownership	4	57
	Ownership	5	61
	Ownership	6	40
	Ownership	7	48
	ReferencePrice	5
	StaticPriceBandLowerLimit	0.6
	StaticPriceBandUpperLimit	0.8
	TotalShares	100
	OwnershipUpperLimit	0.2
	TickSize	1
	LotSize	1
Limit	3	7	5	2	8	SELL	0	FAK	0
NewOrderRs	Eliminated
	Trades	0
	Orders	1
	Order	Iceberg	1	5	1	4	7	SELL	0	---	3
	Credits	7
	Credit	1	4
	Credit	2	7
	Credit	3	16
	Credit	4	13
	Credit	5	11
	Credit	6	17
	Credit	7	8
	Ownerships	7
	Ownership	1	21
	Ownership	2	21
	Ownership	3	71
	Ownership	4	57
	Ownership	5	61
	Ownership	6	40
	Ownership	7	48
	ReferencePrice	5
	StaticPriceBandLowerLimit	0.6
	StaticPriceBandUpperLimit	0.8
	TotalShares	100
	OwnershipUpperLimit	0.2
	TickSize	1
	LotSize	1
Limit	4	7	3	8	3	BUY 	0	---	0
NewOrderRs	Rejected
	Trades	0
	Orders	1
	Order	Iceberg	1	5	1	4	7	SELL	0	---	3
	Credits	7
	Credit	1	4
	Credit	2	7
	Credit	3	16
	Credit	4	13
	Credit	5	11
	Credit	6	17
	Credit	7	8
	Ownerships	7
	Ownership	1	21
	Ownership	2	21
	Ownership	3	71
	Ownership	4	57
	Ownership	5	61
	Ownership	6	40
	Ownership	7	48
	ReferencePrice	5
	StaticPriceBandLowerLimit	0.6
	StaticPriceBandUpperLimit	0.8
	TotalShares	100
	OwnershipUpperLimit	0.2
	TickSize	1
	LotSize	1
CancelOrderRs	Rejected
	Orders	1
	Order	Iceberg	1	5	1	4	7	SELL	0	---	3
	Credits	7
	Credit	1	4
	Credit	2	7
	Credit	3	16
	Credit	4	13
	Credit	5	11
	Credit	6	17
	Credit	7	8
	Ownerships	7
	Ownership	1	21
	Ownership	2	21
	Ownership	3	71
	Ownership	4	57
	Ownership	5	61
	Ownership	6	40
	Ownership	7	48
	ReferencePrice	5
	StaticPriceBandLowerLimit	0.6
	StaticPriceBandUpperLimit	0.8
	TotalShares	100
	OwnershipUpperLimit	0.2
	TickSize	1
	LotSize	1
Limit	6	7	6	9	3	SELL	2	---	0
NewOrderRs	Eliminated
	Trades	0
	Orders	1
	Order	Iceberg	1	5	1	4	7	SELL	0	---	3
	Credits	7
	Credit	1	4
	Credit	2	7
	Credit	3	16
	Credit	4	13
	Credit	5	11
	Credit	6	17
	Credit	7	8
	Ownerships	7
	Ownership	1	21
	Ownership	2	21
	Ownership	3	71
	Ownership	4	57
	Ownership	5	61
	Ownership	6	40
	Ownership	7	48
	ReferencePrice	5
	StaticPriceBandLowerLimit	0.6
	StaticPriceBandUpperLimit	0.8
	TotalShares	100
	OwnershipUpperLimit	0.2
	TickSize	1
	LotSize	1
Limit	7	2	3	6	5	BUY 	0	FAK	0
NewOrderRs	Rejected
	Trades	0
	Orders	1
	Order	Iceberg	1	5	1	4	7	SELL	0	---	3
	Credits	7
	Credit	1	4
	Credit	2	7
	Credit	3	16
	Credit	4	13
	Credit	5	11
	Credit	6	17
	Credit	7	8
	Ownerships	7
	Ownership	1	21
	Ownership	2	21
	Ownership	3	71
	Ownership	4	57
	Ownership	5	61
	Ownership	6	40
	Ownership	7	48
	ReferencePrice	5
	StaticPriceBandLowerLimit	0.6
	StaticPriceBandUpperLimit	0.8
	TotalShares	100
	OwnershipUpperLimit	0.2
	TickSize	1
	LotSize	1
Iceberg	8	7	2	9	2	SELL	0	---	0
NewOrderRs	Accepted
	Trades	0
	Orders	2
	Order	Iceberg	1	5	1	4	7	SELL	0	---	3
	Order	Iceberg	8	7	2	9	2	SELL	0	---	1
	Credits	7
	Credit	1	4
	Credit	2	7
	Credit	3	16
	Credit	4	13
	Credit	5	11
	Credit	6	17
	Credit	7	8
	Ownerships	7
	Ownership	1	21
	Ownership	2	21
	Ownership	3	71
	Ownership	4	57
	Ownership	5	61
	Ownership	6	40
	Ownership	7	48
	ReferencePrice	5
	StaticPriceBandLowerLimit	0.6
	StaticPriceBandUpperLimit	0.8
	TotalShares	100
	OwnershipUpperLimit	0.2
	TickSize	1
	LotSize	1
Limit	9	3	4	4	3	BUY 	1	---	0
NewOrderRs	Rejected
	Trades	0
	Orders	2
	Order	Iceberg	1	5	1	4	7	SELL	0	---	3
	Order	Iceberg	8	7	2	9	2	SELL	0	---	1
	Credits	7
	Credit	1	4
	Credit	2	7
	Credit	3	16
	Credit	4	13
	Credit	5	11
	Credit	6	17
	Credit	7	8
	Ownerships	7
	Ownership	1	21
	Ownership	2	21
	Ownership	3	71
	Ownership	4	57
	Ownership	5	61
	Ownership	6	40
	Ownership	7	48
	ReferencePrice	5
	StaticPriceBandLowerLimit	0.6
	StaticPriceBandUpperLimit	0.8
	TotalShares	100
	OwnershipUpperLimit	0.2
	TickSize	1
	LotSize	1
Iceberg	10	3	4	6	3	BUY 	2	---	0
ReplaceOrderRs	Rejected
	Trades	0
	Orders	2
	Order	Iceberg	1	5	1	4	7	SELL	0	---	3
	Order	Iceberg	8	7	2	9	2	SELL	0	---	1
	Credits	7
	Credit	1	4
	Credit	2	7
	Credit	3	16
	Credit	4	13
	Credit	5	11
	Credit	6	17
	Credit	7	8
	Ownerships	7
	Ownership	1	21
	Ownership	2	21
	Ownership	3	71
	Ownership	4	57
	Ownership	5	61
	Ownership	6	40
	Ownership	7	48
	ReferencePrice	5
	StaticPriceBandLowerLimit	0.6
	StaticPriceBandUpperLimit	0.8
	TotalShares	100
	OwnershipUpperLimit	0.2
	TickSize	1
	LotSize	1
Limit	11	6	1	3	6	SELL	0	---	0
NewOrderRs	Accepted
	Trades	0
	Orders	3
	Order	Limit	11	6	1	3	6	SELL	0	---	0
	Order	Iceberg	1	5	1	4	7	SELL	0	---	3
	Order	Iceberg	8	7	2	9	2	SELL	0	---	1
	Credits	7
	Credit	1	4
	Credit	2	7
	Credit	3	16
	Credit	4	13
	Credit	5	11
	Credit	6	17
	Credit	7	8
	Ownerships	7
	Ownership	1	21
	Ownership	2	21
	Ownership	3	71
	Ownership	4	57
	Ownership	5	61
	Ownership	6	40
	Ownership	7	48
	ReferencePrice	5
	StaticPriceBandLowerLimit	0.6
	StaticPriceBandUpperLimit	0.8
	TotalShares	100
	OwnershipUpperLimit	0.2
	TickSize	1
	LotSize	1
Limit	12	1	4	4	5	SELL	4	---	0
NewOrderRs	Eliminated
	Trades	0
	Orders	3
	Order	Limit	11	6	1	3	6	SELL	0	---	0
	Order	Iceberg	1	5	1	4	7	SELL	0	---	3
	Order	Iceberg	8	7	2	9	2	SELL	0	---	1
	Credits	7
	Credit	1	4
	Credit	2	7
	Credit	3	16
	Credit	4	13
	Credit	5	11
	Credit	6	17
	Credit	7	8
	Ownerships	7
	Ownership	1	21
	Ownership	2	21
	Ownership	3	71
	Ownership	4	57
	Ownership	5	61
	Ownership	6	40
	Ownership	7	48
	ReferencePrice	5
	StaticPriceBandLowerLimit	0.6
	StaticPriceBandUpperLimit	0.8
	TotalShares	100
	OwnershipUpperLimit	0.2
	TickSize	1
	LotSize	1
Iceberg	13	2	3	3	6	SELL	0	---	0
NewOrderRs	Accepted
	Trades	0
	Orders	4
	Order	Limit	11	6	1	3	6	SELL	0	---	0
	Order	Iceberg	13	2	3	3	6	SELL	0	---	6
	Order	Iceberg	1	5	1	4	7	SELL	0	---	3
	Order	Iceberg	8	7	2	9	2	SELL	0	---	1
	Credits	7
	Credit	1	4
	Credit	2	7
	Credit	3	16
	Credit	4	13
	Credit	5	11
	Credit	6	17
	Credit	7	8
	Ownerships	7
	Ownership	1	21
	Ownership	2	21
	Ownership	3	71
	Ownership	4	57
	Ownership	5	61
	Ownership	6	40
	Ownership	7	48
	ReferencePrice	5
	StaticPriceBandLowerLimit	0.6
	StaticPriceBandUpperLimit	0.8
	TotalShares	100
	OwnershipUpperLimit	0.2
	TickSize	1
	LotSize	1
Iceberg	14	6	1	9	6	SELL	0	---	0
NewOrderRs	Accepted
	Trades	0
	Orders	5
	Order	Limit	11	6	1	3	6	SELL	0	---	0
	Order	Iceberg	13	2	3	3	6	SELL	0	---	6
	Order	Iceberg	1	5	1	4	7	SELL	0	---	3
	Order	Iceberg	8	7	2	9	2	SELL	0	---	1
	Order	Iceberg	14	6	1	9	6	SELL	0	---	3
	Credits	7
	Credit	1	4
	Credit	2	7
	Credit	3	16
	Credit	4	13
	Credit	5	11
	Credit	6	17
	Credit	7	8
	Ownerships	7
	Ownership	1	21
	Ownership	2	21
	Ownership	3	71
	Ownership	4	57
	Ownership	5	61
	Ownership	6	40
	Ownership	7	48
	ReferencePrice	5
	StaticPriceBandLowerLimit	0.6
	StaticPriceBandUpperLimit	0.8
	TotalShares	100
	OwnershipUpperLimit	0.2
	TickSize	1
	LotSize	1
CancelOrderRs	Accepted
	Orders	4
	Order	Limit	11	6	1	3	6	SELL	0	---	0
	Order	Iceberg	13	2	3	3	6	SELL	0	---	6
	Order	Iceberg	1	5	1	4	7	SELL	0	---	3
	Order	Iceberg	8	7	2	9	2	SELL	0	---	1
	Credits	7
	Credit	1	4
	Credit	2	7
	Credit	3	16
	Credit	4	13
	Credit	5	11
	Credit	6	17
	Credit	7	8
	Ownerships	7
	Ownership	1	21
	Ownership	2	21
	Ownership	3	71
	Ownership	4	57
	Ownership	5	61
	Ownership	6	40
	Ownership	7	48
	ReferencePrice	5
	StaticPriceBandLowerLimit	0.6
	StaticPriceBandUpperLimit	0.8
	TotalShares	100
	OwnershipUpperLimit	0.2
	TickSize	1
	LotSize	1
Limit	16	4	1	7	1	BUY 	0	FAK	0
NewOrderRs	Rejected
	Trades	0
	Orders	4
	Order	Limit	11	6	1	3	6	SELL	0	---	0
	Order	Iceberg	13	2	3	3	6	SELL	0	---	6
	Order	Iceberg	1	5	1	4	7	SELL	0	---	3
	Order	Iceberg	8	7	2	9	2	SELL	0	---	1
	Credits	7
	Credit	1	4
